<robot name="DiffDriveRobot">

	<link name="chassis">
		<inertial>
			<mass value="3.0"/>
		</inertial>
        <visual>
            <origin xyz="0.0 0.15 0.1"/>
            <geometry>
                <box size="0.3 0.3 0.15"/>
            </geometry>
            <material name="white"/>
        </visual>
        <collision>
            <origin xyz="0.0 0.15 0.1"/>
            <geometry>
                <box size="0.3 0.3 0.15"/>
            </geometry>
        </collision>
    </link>
	
	<link name="left_wheel">
        <visual>
            <origin xyz="0.0 0.0 0.0" rpy="0.0 1.57075 0.0"/>
            <geometry>
                <cylinder radius="0.1" length="0.02"/>
            </geometry>
            <material name="red"/>
        </visual>
        <collision>
            <origin xyz="0.0 0.0 0.0" rpy="0.0 1.57075 0.0"/>
            <geometry>
                <cylinder radius="0.1" length="0.02"/>
            </geometry>
        </collision>
    </link>
	
	<joint name="left_wheel_joint" type="continuous">
        <origin xyz="0.175 0.1 0.1" rpy="0.0 0.0 0.0"/>
        <parent link="chassis"/>
        <child link="left_wheel"/>
        <axis xyz="1.0 0.0 0.0"/>
		<limit effort="0.03" />
    </joint>
	
	<link name="right_wheel">
        <visual>
            <origin xyz="0.0 0.0 0.0" rpy="0.0 1.57075 0.0"/>
            <geometry>
                <cylinder radius="0.1" length="0.02"/>
            </geometry>
            <material name="blue"/>
        </visual>
        <collision>
            <origin xyz="0.0 0.0 0.0" rpy="0.0 1.57075 0.0"/>
            <geometry>
                <cylinder radius="0.1" length="0.02"/>
            </geometry>
        </collision>
    </link>
	
	<joint name="right_wheel_joint" type="continuous">
        <origin xyz="-0.175 0.1 0.1" rpy="0.0 0.0 0.0"/>
        <parent link="chassis"/>
        <child link="right_wheel"/>
        <axis xyz="1.0 0.0 0.0"/>
		<limit effort="0.03" />
    </joint>
	
	<joint name="caster_joint" type="fixed" extra="free_wheel">
        <origin xyz="0.0 0.24 0.05" rpy="0.0 0.0 0.0"/>
        <parent link="chassis"/>
        <child link="caster_wheel"/>
    </joint>

    <link name="caster_wheel">
        <visual>
            <geometry>
                <sphere radius="0.05"/>
            </geometry>
        <material name="black"/>
        </visual>
        <collision>
            <geometry>
                <sphere radius="0.05"/>
            </geometry>
        </collision>
    </link>
	
	<gobotics>
        <control name="control_robot" type="diff_drive">
            <right_wheel joint="right_wheel_joint"/>
            <left_wheel joint="left_wheel_joint"/>
			<max_speed value="7.0"/>
        </control>
    </gobotics>
	
	<material name="white">
        <color rgba="1 1 1 1"/>
    </material>
	<material name="red">
        <color rgba="1 0 0 1"/>
    </material>
	<material name="green">
        <color rgba="0 1 0 1"/>
    </material>
	<material name="blue">
        <color rgba="0 0 0.8 1"/>
    </material>
    <material name="black">
        <color rgba="0 0 0 1"/>
    </material>
</robot>