<robot name="Prismatic">
	<link name="base_link">
	
		<visual name="" with_col="true">
			<origin xyz="0 0 0" rpy="0 0 0"/>
			<geometry>
			<box size="0.3 0.1 0.1"/>
			</geometry>
			<material name="">
			
			</material>
		</visual>

	</link>
	
	
	<link name="slider">
	
		<visual name="" with_col="true">
			<origin xyz="0 0 0" rpy="0 0 0"/>
			<geometry>
			<box size="0.1 0.1 0.1"/>
			</geometry>
			<material name="">
			<color rgba="0 0.7 0.4 1"/>
			</material>
		</visual>

	</link>

	<joint name="slider_joint" type="prismatic" visible="true">
		<origin xyz="0 0 0.1" rpy="0 0 0"/>
		<parent link="base_link"/>
		<child link="slider"/>
		<axis xyz="1.0 0.0 0.0"/>
		<limit lower="-0.1" upper="0.1" effort="1.0" velocity="0.2"/>
	</joint>

</robot>
