<robot name="Robot Omni">
	<!-- CHASSIS LINK -->
	<link name="base_link">

		<inertial>
			<origin xyz="0 0 0.01" rpy="0 0 0"/>
			<mass value="1"/>
		</inertial>

		<visual name="chassis">
			<origin xyz="0 0 0.06" rpy="0 0 0"/>
			<geometry>
				<cylinder radius="0.12" length="0.1"/>
			</geometry>
			<material name="">
				<color rgba="0 0.1 0.5 1"/>
			</material>
		</visual>

		<visual name="front_flag">
			<origin xyz="0.08 0 0.11" rpy="0 0 0"/>
			<geometry>
				<box size="0.05 0.1 0.01"/>
			</geometry>
			<material name="">
				<color rgba="1 0 0 1"/>
			</material>
		</visual>

		<collision name="chassis">
			<origin xyz="0 0 0.06" rpy="0 0 0"/>
			<geometry>
				<cylinder radius="0.12" length="0.1"/>
			</geometry>
		</collision>

	</link>

	<!-- FRONT RIGHT WHEEL LINK -->
	<link name="wheel_1" extends="omni_wheel">

		<inertial>
			<mass value="0.1"/>
		</inertial>
		<visual name="">
			<origin xyz="0 0.05 0" rpy="1.57 0 0"/>
			<geometry>
				<cylinder radius="0.005" length="0.1"/>
			</geometry>
			<material name="">
				<color rgba="0.2 0.2 0 1"/>
			</material>
		</visual>
	</link>

	<joint name="wheel_1_joint" type="continuous">
		<origin xyz="0.08 -0.13 0.03" rpy="0 0 0.52"/>
		<parent link="base_link"/>
		<child link="wheel_1"/>
		<axis xyz="0.0 1.0 0.0"/>
		<limit effort="100" velocity="5.0"/>
	</joint>

	<!-- FRONT LEFT WHEEL LINK -->
	<link name="wheel_2" extends="omni_wheel">
		<inertial>
			<mass value="0.1"/>
		</inertial>
		<visual name="">
			<origin xyz="0 0.05 0" rpy="1.57 0 0"/>
			<geometry>
				<cylinder radius="0.005" length="0.1"/>
			</geometry>
			<material name="">
				<color rgba="0.2 0.2 0 1"/>
			</material>
		</visual>
	</link>

	<joint name="wheel_2_joint" type="continuous">
		<origin xyz="0.08 0.13 0.03" rpy="0 0 -3.67"/>
		<parent link="base_link"/>
		<child link="wheel_2"/>
		<axis xyz="0.0 1.0 0.0"/>
		<limit effort="100" velocity="5.0"/>
	</joint>

	<!-- BACK RIGHT WHEEL LINK -->
	<link name="wheel_3" extends="omni_wheel">
		<inertial>
			<mass value="0.1"/>
		</inertial>
		<visual name="">
			<origin xyz="0 0.05 0" rpy="1.57 0 0"/>
			<geometry>
				<cylinder radius="0.005" length="0.1"/>
			</geometry>
			<material name="">
				<color rgba="0.2 0.2 0 1"/>
			</material>
		</visual>
	</link>

	<joint name="wheel_3_joint" type="continuous">
		<origin xyz="-0.15 0 0.03" rpy="0 0 -1.57"/>
		<parent link="base_link"/>
		<child link="wheel_3"/>
		<axis xyz="0.0 1.0 0.0"/>
		<limit effort="100" velocity="5.0"/>
	</joint>

	<gobotics name="control_robot" type="3_omni_drive">
		<wheel_1 joint="wheel_1_joint"/>
		<wheel_2 joint="wheel_2_joint"/>
		<wheel_3 joint="wheel_3_joint"/>
		<max_speed value="8.0"/>
	</gobotics>

</robot>
