<robot name="Robot Pioneer Cam">

	<!-- CHASSIS LINK -->
	<link name="base_link">
		<inertial>
			<mass value="1"/>
		</inertial>
		<visual name="chassis">
			<origin xyz="0 0 0.04" rpy="0 0 0"/>
			<geometry>
				<mesh filename="demo/meshes/PioneerChassis.glb" />
			</geometry>
			<material name="">
				<color rgba="0.8 0.8 0.8 1"/>
			</material>
		</visual>
		
		<collision name="chassis">
			<origin xyz="0 0 0.04" rpy="0 0 0"/>
			<geometry>
				<cylinder radius="0.19" length="0.02"/>
			</geometry>
		</collision>

		<visual name="pole">
			<origin xyz="0.1 0 0.07" rpy="0 0 0"/>
			<geometry>
				<cylinder radius="0.02" length="0.07"/>
			</geometry>
			<material name="">
				<color rgba="0 0 0 1"/>
			</material>
		</visual>

	</link>
	
	<!-- RIGHT WHEEL LINK --> 
	<link name="right_wheel">
		<inertial>
			<mass value="1"/>
		</inertial>
		<visual name="wheel">
			<origin xyz="0 0 0" rpy="0 0 0"/>
			<geometry>
				<mesh filename="demo/meshes/PioneerWheel.glb" />
			</geometry>
			
		</visual>
		<visual name="shaft">
			<origin xyz="0 0.02 0" rpy="0 0 0"/>
			<geometry>
				<box size="0.01 0.07 0.01"/>
			</geometry>
			
		</visual>
		<collision>
			<origin xyz="0 0 0" rpy="1.57 0 0"/>
			<geometry>
				<cylinder radius="0.06" length="0.02"/>
			</geometry>
		</collision>
	</link>
	
	<joint name="right_joint" type="continuous">
		<origin xyz="0 -0.16 0.06" rpy="0 0 0"/>
		<parent link="base_link"/>
		<child link="right_wheel"/>
		<axis xyz="0.0 1.0 0.0"/>
		<limit effort="10" velocity="5.0"/>
	</joint>
	
	<!-- LEFT WHEEL LINK -->
	<link name="left_wheel">
		<inertial>
			<mass value="1"/>
		</inertial>
		<visual name="wheel">
			<origin xyz="0 0 0" rpy="0 0 3.1415"/>
			<geometry>
				<mesh filename="demo/meshes/PioneerWheel.glb" />
			</geometry>
			
		</visual>
		
		<visual name="shaft">
			<origin xyz="0 -0.02 0" rpy="0 0 0"/>
			<geometry>
				<box size="0.01 0.07 0.01"/>
			</geometry>
			
		</visual>

		<collision>
			<origin xyz="0 0 0" rpy="1.57 0 0"/>
			<geometry>
				<cylinder radius="0.06" length="0.02"/>
			</geometry>
		</collision>
	</link>
	
	<joint name="left_joint" type="continuous">
		<origin xyz="0 0.16 0.06" rpy="0 0 0"/>
		<parent link="base_link"/>
		<child link="left_wheel"/>
		<axis xyz="0.0 1.0 0.0"/>
		<limit effort="10" velocity="5.0"/>
	</joint>
	
	<!-- BACK CASTER WHEEL LINK -->
	<link name="back_caster_wheel">
		<inertial>
			<mass value="2"/>
			<friction value="0.0" />
		</inertial>
        <visual>
            <geometry>
                <mesh filename="demo/meshes/PioneerCaster.glb" />
            </geometry>
        <material>
			<color rgba="0 0 0 1"/>
		</material>
        </visual>
        <collision>
            <geometry>
                <sphere radius="0.02"/>
            </geometry>
        </collision>
    </link>
	
	<joint name="back_caster_joint" type="fixed">
		<origin xyz="-0.15 0.0 0.0205" rpy="0 0 0"/>
		<parent link="base_link"/>
		<child link="back_caster_wheel"/>
	</joint>
	
	<!-- FRONT CASTER WHEEL LINK -->
	<link name="front_caster_wheel">
		<inertial>
			<mass value="2"/>
			<friction value="0.0" />
		</inertial>
        <visual>
            <geometry>
                <mesh filename="demo/meshes/PioneerCaster.glb" />
            </geometry>
        <material>
			<color rgba="0 0 0 1"/>
		</material>
        </visual>
        <collision>
            <geometry>
                <sphere radius="0.02"/>
            </geometry>
        </collision>
    </link>
	
	<joint name="front_caster_joint" type="fixed">
		<origin xyz="0.15 0.0 0.0205" rpy="0 0 0"/>
		<parent link="base_link"/>
		<child link="front_caster_wheel"/>
	</joint>
	
	<gobotics name="control_robot" type="diff_drive">
        <right_wheel joint="right_joint"/>
        <left_wheel joint="left_joint"/>
		<max_speed value="8.0"/>
    </gobotics>
	
	<!-- HALF-LIDAR SENSOR -->
	<sensor name="front_cam" type="camera" update_rate="">
		<origin xyz="0.1 0 0.15" rpy="0 0 0"/>
		<parent link="base_link"/>
	</sensor>

</robot>
