<robot name="Robot Mecanum Wrench">
	<!-- CHASSIS LINK -->
	<link name="base_link">
		
		<inertial>
		<origin xyz="0 0 0.01" rpy="0 0 0"/>
			<mass value="1"/>
		</inertial>

		<visual name="chassis">
			<origin xyz="0 0 0.06" rpy="0 0 0"/>
			<geometry>
				<cylinder radius="0.12" length="0.1"/>
			</geometry>
			<material name="">
				<color rgba="0 0.1 0.5 1"/>
			</material>
		</visual>
		
		<visual name="front_flag">
			<origin xyz="0.08 0 0.11" rpy="0 0 0"/>
			<geometry>
				<box size="0.05 0.1 0.01"/>
			</geometry>
			<material name="">
			<color rgba="1 0 0 1"/>
			</material>
		</visual>

		<collision name="chassis">
			<origin xyz="0 0 0.06" rpy="0 0 0"/>
			<geometry>
				<cylinder radius="0.12" length="0.1"/>
			</geometry>
		</collision>

	</link>
	
	<!-- FRONT RIGHT WHEEL LINK --> 
	<link name="front_right_wheel" extends="right_mecanum_wheel">

		<inertial>
			<mass value="0.1"/>
		</inertial>
		<visual name="">
			<origin xyz="0 0.05 0" rpy="1.57 0 0"/>
			<geometry>
			<cylinder radius="0.005" length="0.1"/>
			</geometry>
			<material name="">
			<color rgba="0.2 0.2 0 1"/>
			</material>
		</visual>
	</link>
	
	<joint name="front_right_joint" type="continuous">
		<origin xyz="0.11 -0.11 0.03" rpy="0 0 0"/>
		<parent link="base_link"/>
		<child link="front_right_wheel"/>
		<axis xyz="0.0 1.0 0.0"/>
		<limit effort="100" velocity="5.0"/>
	</joint>
	
	<!-- FRONT LEFT WHEEL LINK -->
	<link name="front_left_wheel" extends="left_mecanum_wheel">
		<inertial>
			<mass value="0.1"/>
		</inertial>
		<visual name="">
			<origin xyz="0 -0.05 0" rpy="1.57 0 0"/>
			<geometry>
			<cylinder radius="0.005" length="0.1"/>
			</geometry>
			<material name="">
			<color rgba="0.2 0.2 0 1"/>
			</material>
		</visual>
	</link>
	
	<joint name="front_left_joint" type="continuous">
		<origin xyz="0.11 0.11 0.03" rpy="0 0 0"/>
		<parent link="base_link"/>
		<child link="front_left_wheel"/>
		<axis xyz="0.0 1.0 0.0"/>
		<limit effort="100" velocity="5.0"/>
	</joint>
	
	<!-- BACK RIGHT WHEEL LINK --> 
	<link name="back_right_wheel" extends="left_mecanum_wheel">
		<inertial>
			<mass value="0.1"/>
		</inertial>
		<visual name="">
			<origin xyz="0 0.05 0" rpy="1.57 0 0"/>
			<geometry>
			<cylinder radius="0.005" length="0.1"/>
			</geometry>
			<material name="">
			<color rgba="0.2 0.2 0 1"/>
			</material>
		</visual>
	</link>
	
	<joint name="back_right_joint" type="continuous">
		<origin xyz="-0.11 -0.11 0.03" rpy="0 0 0"/>
		<parent link="base_link"/>
		<child link="back_right_wheel"/>
		<axis xyz="0.0 1.0 0.0"/>
		<limit effort="100" velocity="5.0"/>
	</joint>
	
	<!-- BACK LEFT WHEEL LINK -->
	<link name="back_left_wheel" extends="right_mecanum_wheel">
		<inertial>
			<mass value="0.1"/>
		</inertial>
		<visual name="">
			<origin xyz="0 -0.05 0" rpy="1.57 0 0"/>
			<geometry>
			<cylinder radius="0.005" length="0.1"/>
			</geometry>
			<material name="">
			<color rgba="0.2 0.2 0 1"/>
			</material>
		</visual>
	</link>
	
	<joint name="back_left_joint" type="continuous">
		<origin xyz="-0.11 0.11 0.03" rpy="0 0 0"/>
		<parent link="base_link"/>
		<child link="back_left_wheel"/>
		<axis xyz="0.0 1.0 0.0"/>
		<limit effort="100" velocity="5.0"/>
	</joint>
	
	<gobotics name="control_robot" type="4_mecanum_drive">
        <front_right_wheel joint="front_right_joint"/>
        <front_left_wheel joint="front_left_joint"/>
		<back_right_wheel joint="back_right_joint"/>
        <back_left_wheel joint="back_left_joint"/>
		<max_speed value="8.0"/>
    </gobotics>
	
	<!-- ELEVATOR LINK -->
	
	<link name="elevator_link">
		
		<visual name="elevator">
			<origin xyz="0 0 0" rpy="0 0 0"/>
			<geometry>
				<box size="0.02 0.12 0.04"/>
			</geometry>
			<material name="">
			<color rgba="0 1 0 1"/>
			</material>
		</visual>

		<collision name="">
			<origin xyz="0 0 0" rpy="0 0 0"/>
			<geometry>
				<box size="0.02 0.12 0.04"/>
			</geometry>
		</collision>
		
		
		<visual name="slider">
			<origin xyz="-0.01 0 0" rpy="0 0 0"/>
			<geometry>
			<box size="0.03 0.02 0.03"/>
			</geometry>
			<material name="">
			<color rgba="0 1 0 1"/>
			</material>
		</visual>

		<collision name="">
			<origin xyz="-0.01 0 0" rpy="0 0 0"/>
			<geometry>
			<box size="0.03 0.02 0.03"/>
			</geometry>
		</collision>

		<inertial>
			<mass value="0.1"/>
		</inertial>
	</link>
	
	<joint name="elevator_joint" type="prismatic">
		<origin xyz="0.14 0 0.05" rpy="0 0 0"/>
		<parent link="base_link"/>
		<child link="elevator_link"/>
		<axis xyz="0.0 0.0 1.0"/>
		<limit lower="0.0" upper="0.1" effort="100" velocity="0.3"/>
	</joint>

	<!-- LEFT WRENCH LINK -->
	
	<link name="left_wrench_link">

		<visual name="moveable_wrench">
			<origin xyz="0.035 0 0" rpy="0 0 0"/>
			<geometry>
			<box size="0.1 0.01 0.04"/>
			</geometry>
			<material name="">
			<color rgba="0 0 1 1"/>
			</material>
		</visual>

		<collision name="">
			<origin xyz="0.035 0 0" rpy="0 0 0"/>
			<geometry>
			<box size="0.1 0.01 0.04"/>
			</geometry>
		</collision>

		<inertial>
			<mass value="0.1"/>
		</inertial>
	</link>

	<joint name="left_wrench_joint" type="revolute">
		<origin xyz="0 0.05 0.01" rpy="0 0 0"/>
		<parent link="elevator_link"/>
		<child link="left_wrench_link"/>
		<axis xyz="0.0 0.0 1.0"/>
		<limit lower="-1.57" upper="0" effort="10.0" velocity="1.0"/>
	</joint>
	
	<!-- RIGHT WRENCH LINK -->
	
	<link name="right_wrench_link">

		<visual name="moveable_wrench">
			<origin xyz="0.035 0 0" rpy="0 0 0"/>
			<geometry>
			<box size="0.1 0.01 0.04"/>
			</geometry>
			<material name="">
			<color rgba="0 0 1 1"/>
			</material>
		</visual>

		<collision name="">
			<origin xyz="0.035 0 0" rpy="0 0 0"/>
			<geometry>
			<box size="0.1 0.01 0.04"/>
			</geometry>
		</collision>

		<inertial>
			<mass value="0.1"/>
		</inertial>
	</link>

	<joint name="right_wrench_joint" type="revolute">
		<origin xyz="0 -0.05 0.01" rpy="0 0 0"/>
		<parent link="elevator_link"/>
		<child link="right_wrench_link"/>
		<axis xyz="0.0 0.0 1.0"/>
		<limit lower="0" upper="1.57" effort="10.0" velocity="1.0"/>
	</joint>
	
	<gobotics name="control_wrench" type="grouped_joints">
		<input name="wrench_in" lower="0" upper="1"/>
		<output joint="left_wrench_joint" factor="-0.5"/>
		<output joint="right_wrench_joint" factor="0.5"/>
    </gobotics>
	
</robot>
