<robot name="Robot with wrench">
	<!-- CHASSIS LINK -->
	<link name="base_link">
		
		<inertial>
			<mass value="5"/>
		</inertial>

		<visual name="chassis">
			<origin xyz="0 0 0.06" rpy="0 0 0"/>
			<geometry>
				<cylinder radius="0.12" length="0.1"/>
			</geometry>
			<material name="">
				<color rgba="0 0.1 0.5 1"/>
			</material>
		</visual>
		
		<visual name="front_flag">
			<origin xyz="0.08 0 0.11" rpy="0 0 0"/>
			<geometry>
				<box size="0.05 0.1 0.01"/>
			</geometry>
			<material name="">
				<color rgba="1 0 0 1"/>
			</material>
		</visual>

		<collision name="chassis">
			<origin xyz="0 0 0.06" rpy="0 0 0"/>
			<geometry>
				<cylinder radius="0.12" length="0.1"/>
			</geometry>
		</collision>
		
		<visual name="elevator">
			<origin xyz="0.11 0 0.1" rpy="0 0 0"/>
			<geometry>
			<box size="0.02 0.05 0.14"/>
			</geometry>
			<material name="">
				<color rgba="0 0.1 0.5 1"/>
			</material>
		</visual>
	</link>
	
	<!-- RIGHT WHEEL LINK --> 
	<link name="right_wheel">
		<inertial>
			<mass value="1"/>
		</inertial>
		<visual>
			<origin xyz="0 0 0" rpy="1.57 0 0"/>
			<geometry>
				<cylinder radius="0.05" length="0.02"/>
			</geometry>
			<material>
				<color rgba="0 0 1 1"/>
			</material>
		</visual>

		<collision>
			<origin xyz="0 0 0" rpy="1.57 0 0"/>
			<geometry>
				<cylinder radius="0.05" length="0.02"/>
			</geometry>
		</collision>

	</link>
	
	<joint name="right_joint" type="continuous">
		<origin xyz="0 -0.12 0.05" rpy="0 0 0"/>
		<parent link="base_link"/>
		<child link="right_wheel"/>
		<axis xyz="0.0 1.0 0.0"/>
		<limit effort="10" velocity="5.0"/>
	</joint>
	
	<!-- LEFT WHEEL LINK -->
	<link name="left_wheel">
		<inertial>
			<mass value="1"/>
		</inertial>
		<visual>
			<origin xyz="0 0 0" rpy="1.57 0 0"/>
			<geometry>
				<cylinder radius="0.05" length="0.02"/>
			</geometry>
			<material>
				<color rgba="0 0 1 1"/>
			</material>
		</visual>

		<collision>
			<origin xyz="0 0 0" rpy="1.57 0 0"/>
			<geometry>
				<cylinder radius="0.05" length="0.02"/>
			</geometry>
		</collision>

	</link>
	
	<joint name="left_joint" type="continuous">
		<origin xyz="0 0.12 0.05" rpy="0 0 0"/>
		<parent link="base_link"/>
		<child link="left_wheel"/>
		<axis xyz="0.0 1.0 0.0"/>
		<limit effort="10" velocity="5.0"/>
	</joint>
	
	<!-- BACK CASTER WHEEL LINK -->
	<link name="back_caster_wheel">
        <visual>
            <geometry>
                <sphere radius="0.02"/>
            </geometry>
        <material>
			<color rgba="0 0 0 1"/>
		</material>
        </visual>
		
        <collision>
            <geometry>
				<!--><box size="0.1 0.1 0.04"/> -->
                <sphere radius="0.02"/>
            </geometry>
        </collision>
		
		<inertial>
			<mass value="0.1"/>
			<friction value="0.0" />
		</inertial>

    </link>
	
	<joint name="back_caster_joint" type="fixed">
		<origin xyz="-0.10 0.0 0.021" rpy="0 0 0"/>
		<parent link="base_link"/>
		<child link="back_caster_wheel"/>
	</joint>
	
	<!-- FRONT CASTER WHEEL LINK -->
	<link name="front_caster_wheel">
        <visual>
            <geometry>
                <sphere radius="0.02"/>
            </geometry>
        <material>
			<color rgba="0 0 0 1"/>
		</material>
        </visual>
		
        <collision>
            <geometry>
				<!--><box size="0.1 0.1 0.04"/> -->
                <sphere radius="0.02"/>
            </geometry>
        </collision>
		
		<inertial>
			<mass value="2"/>
			<friction value="0.0" />
		</inertial>

    </link>
	
	<joint name="front_caster_joint" type="fixed">
		<origin xyz="0.10 0.0 0.021" rpy="0 0 0"/>
		<parent link="base_link"/>
		<child link="front_caster_wheel"/>
	</joint>
	
	<!-- ELEVATOR LINK -->
	
	<link name="elevator_link">
		
		<visual name="elevator">
			<origin xyz="0 0 0" rpy="0 0 0"/>
			<geometry>
				<box size="0.02 0.12 0.04"/>
			</geometry>
			<material name="">
			<color rgba="0 1 0 1"/>
			</material>
		</visual>

		<collision name="">
			<origin xyz="0 0 0" rpy="0 0 0"/>
			<geometry>
				<box size="0.02 0.12 0.04"/>
			</geometry>
		</collision>
		
		
		<visual name="slider">
			<origin xyz="-0.01 0 0" rpy="0 0 0"/>
			<geometry>
			<box size="0.03 0.02 0.03"/>
			</geometry>
			<material name="">
			<color rgba="0 1 0 1"/>
			</material>
		</visual>

		<collision name="">
			<origin xyz="-0.01 0 0" rpy="0 0 0"/>
			<geometry>
			<box size="0.03 0.02 0.03"/>
			</geometry>
		</collision>

		<inertial>
			<mass value="0.1"/>
		</inertial>
	</link>
	
	<joint name="elevator_joint" type="prismatic">
		<origin xyz="0.14 0 0.05" rpy="0 0 0"/>
		<parent link="base_link"/>
		<child link="elevator_link"/>
		<axis xyz="0.0 0.0 1.0"/>
		<limit lower="0.0" upper="0.1" effort="10.0" velocity="0.5"/>
	</joint>

	<!-- LEFT WRENCH LINK -->
	
	<link name="left_wrench_link">

		<visual name="moveable_wrench">
			<origin xyz="0.035 0 0" rpy="0 0 0"/>
			<geometry>
			<box size="0.1 0.01 0.04"/>
			</geometry>
			<material name="">
			<color rgba="0 0 1 1"/>
			</material>
		</visual>

		<collision name="">
			<origin xyz="0.035 0 0" rpy="0 0 0"/>
			<geometry>
			<box size="0.1 0.01 0.04"/>
			</geometry>
		</collision>

		<inertial>
			<mass value="0.1"/>
		</inertial>
	</link>

	<joint name="left_wrench_joint" type="revolute">
		<origin xyz="0 0.05 0.01" rpy="0 0 0"/>
		<parent link="elevator_link"/>
		<child link="left_wrench_link"/>
		<axis xyz="0.0 0.0 1.0"/>
		<limit lower="-1.57" upper="0" effort="10.0" velocity="1.0"/>
	</joint>
	
	<!-- RIGHT WRENCH LINK -->
	
	<link name="right_wrench_link">

		<visual name="moveable_wrench">
			<origin xyz="0.035 0 0" rpy="0 0 0"/>
			<geometry>
			<box size="0.1 0.01 0.04"/>
			</geometry>
			<material name="">
			<color rgba="0 0 1 1"/>
			</material>
		</visual>

		<collision name="">
			<origin xyz="0.035 0 0" rpy="0 0 0"/>
			<geometry>
			<box size="0.1 0.01 0.04"/>
			</geometry>
		</collision>

		<inertial>
			<mass value="0.1"/>
		</inertial>
	</link>

	<joint name="right_wrench_joint" type="revolute">
		<origin xyz="0 -0.05 0.01" rpy="0 0 0"/>
		<parent link="elevator_link"/>
		<child link="right_wrench_link"/>
		<axis xyz="0.0 0.0 1.0"/>
		<limit lower="0" upper="1.57" effort="10.0" velocity="1.0"/>
	</joint>
	
	<gobotics name="control_robot" type="diff_drive">
        <right_wheel joint="right_joint"/>
        <left_wheel joint="left_joint"/>
		<max_speed value="6.0"/>
    </gobotics>
	
	<gobotics name="control_wrench" type="grouped_joints">
		<input name="wrench_in" lower="0" upper="1"/>
		<output joint="left_wrench_joint" factor="-0.5"/>
		<output joint="right_wrench_joint" factor="0.5"/>
    </gobotics>
</robot>
