<robot name="Slider">
	<link name="base_link">
	
		<visual name="">
			<origin xyz="0 0 0.025" rpy="0 0 0"/>
			<geometry>
				<box size="0.4 0.1 0.05"/>
			</geometry>
			<material>
			<color rgba="1 1 0 1"/>
			</material>
		</visual>

		<collision name="">
			<origin xyz="0 0 0.025" rpy="0 0 0"/>
			<geometry>
				<box size="0.4 0.1 0.05"/>
			</geometry>
		</collision>

		<inertial>
			<mass value="1"/>
		</inertial>

	</link>
	
	<link name="arm">
	
		<visual name="arm">
			<origin xyz="0.1 0.0 0" rpy="0 0 0"/>
			<geometry>
				<box size="0.3 0.05 0.1"/>
			</geometry>
			<material>
			<color rgba="0.5 0 0.5 1"/>
			</material>
		</visual>
		
		<visual name="shaft">
			<origin xyz="0 0 0" rpy="1.57 0 0"/>
			<geometry>
			<cylinder radius="0.01" length="0.12"/>
			</geometry>
			<material name="">
			
			</material>
		</visual>


		<collision name="">
			<origin xyz="0.1 0.0 0" rpy="0 0 0"/>
			<geometry>
				<box size="0.3 0.05 0.1"/>
			</geometry>
		</collision>

		<inertial>
			<mass value="0.1"/>
		</inertial>

	</link>

	<joint name="arm servo" type="prismatic">
		<origin xyz="0 0 0.06" rpy="0 0 0"/>
		<parent link="base_link"/>
		<child link="arm"/>
		<axis xyz="1.0 0.0 0.0"/>
		<limit lower="-0.1" upper="0.2" velocity="0.2"/>
	</joint>

</robot>
